C:\Users\Aliff Fahmi\Documents\GitHub\Local-LLM-and-OpenAI-PDF-QA\venv\Lib\site-packages\huggingface_hub\utils\_deprecation.py:127: FutureWarning: '__init__' (from 'huggingface_hub.inference_api') is deprecated and will be removed from version '0.19.0'. `InferenceApi` client is deprecated in favor of the more feature-complete `InferenceClient`. Check out this guide to learn how to convert your script to use it: https://huggingface.co/docs/huggingface_hub/guides/inference#legacy-inferenceapi-client.
  warnings.warn(warning_message, FutureWarning)
2023-11-17 08:50:45.253 Uncaught app exception
Traceback (most recent call last):
  File "C:\Users\Aliff Fahmi\Documents\GitHub\Local-LLM-and-OpenAI-PDF-QA\venv\Lib\site-packages\urllib3\connection.py", line 203, in _new_conn
    sock = connection.create_connection(
           ^^^^^^^^^^^^^^^^^^^^^^^^^^^^^
  File "C:\Users\Aliff Fahmi\Documents\GitHub\Local-LLM-and-OpenAI-PDF-QA\venv\Lib\site-packages\urllib3\util\connection.py", line 60, in create_connection
    for res in socket.getaddrinfo(host, port, family, socket.SOCK_STREAM):
               ^^^^^^^^^^^^^^^^^^^^^^^^^^^^^^^^^^^^^^^^^^^^^^^^^^^^^^^^^^
  File "C:\Users\Aliff Fahmi\.pyenv\pyenv-win\versions\3.11.6\Lib\socket.py", line 962, in getaddrinfo
    for res in _socket.getaddrinfo(host, port, family, type, proto, flags):
               ^^^^^^^^^^^^^^^^^^^^^^^^^^^^^^^^^^^^^^^^^^^^^^^^^^^^^^^^^^^
socket.gaierror: [Errno 11001] getaddrinfo failed

The above exception was the direct cause of the following exception:

Traceback (most recent call last):
  File "C:\Users\Aliff Fahmi\Documents\GitHub\Local-LLM-and-OpenAI-PDF-QA\venv\Lib\site-packages\urllib3\connectionpool.py", line 790, in urlopen
    response = self._make_request(
               ^^^^^^^^^^^^^^^^^^^
  File "C:\Users\Aliff Fahmi\Documents\GitHub\Local-LLM-and-OpenAI-PDF-QA\venv\Lib\site-packages\urllib3\connectionpool.py", line 491, in _make_request
    raise new_e
  File "C:\Users\Aliff Fahmi\Documents\GitHub\Local-LLM-and-OpenAI-PDF-QA\venv\Lib\site-packages\urllib3\connectionpool.py", line 467, in _make_request
    self._validate_conn(conn)
  File "C:\Users\Aliff Fahmi\Documents\GitHub\Local-LLM-and-OpenAI-PDF-QA\venv\Lib\site-packages\urllib3\connectionpool.py", line 1096, in _validate_conn
    conn.connect()
  File "C:\Users\Aliff Fahmi\Documents\GitHub\Local-LLM-and-OpenAI-PDF-QA\venv\Lib\site-packages\urllib3\connection.py", line 611, in connect
    self.sock = sock = self._new_conn()
                       ^^^^^^^^^^^^^^^^
  File "C:\Users\Aliff Fahmi\Documents\GitHub\Local-LLM-and-OpenAI-PDF-QA\venv\Lib\site-packages\urllib3\connection.py", line 210, in _new_conn
    raise NameResolutionError(self.host, self, e) from e
urllib3.exceptions.NameResolutionError: <urllib3.connection.HTTPSConnection object at 0x000001C2240CD790>: Failed to resolve 'huggingface.co' ([Errno 11001] getaddrinfo failed)

The above exception was the direct cause of the following exception:

Traceback (most recent call last):
  File "C:\Users\Aliff Fahmi\Documents\GitHub\Local-LLM-and-OpenAI-PDF-QA\venv\Lib\site-packages\requests\adapters.py", line 486, in send
    resp = conn.urlopen(
           ^^^^^^^^^^^^^
  File "C:\Users\Aliff Fahmi\Documents\GitHub\Local-LLM-and-OpenAI-PDF-QA\venv\Lib\site-packages\urllib3\connectionpool.py", line 844, in urlopen
    retries = retries.increment(
              ^^^^^^^^^^^^^^^^^^
  File "C:\Users\Aliff Fahmi\Documents\GitHub\Local-LLM-and-OpenAI-PDF-QA\venv\Lib\site-packages\urllib3\util\retry.py", line 515, in increment
    raise MaxRetryError(_pool, url, reason) from reason  # type: ignore[arg-type]
    ^^^^^^^^^^^^^^^^^^^^^^^^^^^^^^^^^^^^^^^^^^^^^^^^^^^
urllib3.exceptions.MaxRetryError: HTTPSConnectionPool(host='huggingface.co', port=443): Max retries exceeded with url: /api/models/google/flan-t5-xxl (Caused by NameResolutionError("<urllib3.connection.HTTPSConnection object at 0x000001C2240CD790>: Failed to resolve 'huggingface.co' ([Errno 11001] getaddrinfo failed)"))

During handling of the above exception, another exception occurred:

Traceback (most recent call last):
  File "C:\Users\Aliff Fahmi\Documents\GitHub\Local-LLM-and-OpenAI-PDF-QA\venv\Lib\site-packages\streamlit\runtime\scriptrunner\script_runner.py", line 534, in _run_script
    exec(code, module.__dict__)
  File "C:\Users\Aliff Fahmi\Documents\GitHub\Local-LLM-and-OpenAI-PDF-QA\app.py", line 95, in <module>
    main()
  File "C:\Users\Aliff Fahmi\Documents\GitHub\Local-LLM-and-OpenAI-PDF-QA\app.py", line 90, in main
    st.session_state.converse = get_converse_chain(vectorstore)
                                ^^^^^^^^^^^^^^^^^^^^^^^^^^^^^^^
  File "C:\Users\Aliff Fahmi\Documents\GitHub\Local-LLM-and-OpenAI-PDF-QA\app.py", line 42, in get_converse_chain
    llm = HuggingFaceHub(
          ^^^^^^^^^^^^^^^
  File "C:\Users\Aliff Fahmi\Documents\GitHub\Local-LLM-and-OpenAI-PDF-QA\venv\Lib\site-packages\langchain\load\serializable.py", line 97, in __init__
    super().__init__(**kwargs)
  File "C:\Users\Aliff Fahmi\Documents\GitHub\Local-LLM-and-OpenAI-PDF-QA\venv\Lib\site-packages\pydantic\v1\main.py", line 339, in __init__
    values, fields_set, validation_error = validate_model(__pydantic_self__.__class__, data)
                                           ^^^^^^^^^^^^^^^^^^^^^^^^^^^^^^^^^^^^^^^^^^^^^^^^^
  File "C:\Users\Aliff Fahmi\Documents\GitHub\Local-LLM-and-OpenAI-PDF-QA\venv\Lib\site-packages\pydantic\v1\main.py", line 1102, in validate_model
    values = validator(cls_, values)
             ^^^^^^^^^^^^^^^^^^^^^^^
  File "C:\Users\Aliff Fahmi\Documents\GitHub\Local-LLM-and-OpenAI-PDF-QA\venv\Lib\site-packages\langchain\llms\huggingface_hub.py", line 55, in validate_environment
    client = InferenceApi(
             ^^^^^^^^^^^^^
  File "C:\Users\Aliff Fahmi\Documents\GitHub\Local-LLM-and-OpenAI-PDF-QA\venv\Lib\site-packages\huggingface_hub\utils\_validators.py", line 118, in _inner_fn
    return fn(*args, **kwargs)
           ^^^^^^^^^^^^^^^^^^^
  File "C:\Users\Aliff Fahmi\Documents\GitHub\Local-LLM-and-OpenAI-PDF-QA\venv\Lib\site-packages\huggingface_hub\utils\_deprecation.py", line 128, in inner_f
    return f(*args, **kwargs)
           ^^^^^^^^^^^^^^^^^^
  File "C:\Users\Aliff Fahmi\Documents\GitHub\Local-LLM-and-OpenAI-PDF-QA\venv\Lib\site-packages\huggingface_hub\inference_api.py", line 131, in __init__
    model_info = HfApi(token=token).model_info(repo_id=repo_id)
                 ^^^^^^^^^^^^^^^^^^^^^^^^^^^^^^^^^^^^^^^^^^^^^^
  File "C:\Users\Aliff Fahmi\Documents\GitHub\Local-LLM-and-OpenAI-PDF-QA\venv\Lib\site-packages\huggingface_hub\utils\_validators.py", line 118, in _inner_fn
    return fn(*args, **kwargs)
           ^^^^^^^^^^^^^^^^^^^
  File "C:\Users\Aliff Fahmi\Documents\GitHub\Local-LLM-and-OpenAI-PDF-QA\venv\Lib\site-packages\huggingface_hub\hf_api.py", line 1697, in model_info
    r = get_session().get(path, headers=headers, timeout=timeout, params=params)
        ^^^^^^^^^^^^^^^^^^^^^^^^^^^^^^^^^^^^^^^^^^^^^^^^^^^^^^^^^^^^^^^^^^^^^^^^
  File "C:\Users\Aliff Fahmi\Documents\GitHub\Local-LLM-and-OpenAI-PDF-QA\venv\Lib\site-packages\requests\sessions.py", line 602, in get
    return self.request("GET", url, **kwargs)
           ^^^^^^^^^^^^^^^^^^^^^^^^^^^^^^^^^^
  File "C:\Users\Aliff Fahmi\Documents\GitHub\Local-LLM-and-OpenAI-PDF-QA\venv\Lib\site-packages\requests\sessions.py", line 589, in request
    resp = self.send(prep, **send_kwargs)
           ^^^^^^^^^^^^^^^^^^^^^^^^^^^^^^
  File "C:\Users\Aliff Fahmi\Documents\GitHub\Local-LLM-and-OpenAI-PDF-QA\venv\Lib\site-packages\requests\sessions.py", line 703, in send
    r = adapter.send(request, **kwargs)
        ^^^^^^^^^^^^^^^^^^^^^^^^^^^^^^^
  File "C:\Users\Aliff Fahmi\Documents\GitHub\Local-LLM-and-OpenAI-PDF-QA\venv\Lib\site-packages\huggingface_hub\utils\_http.py", line 63, in send
    return super().send(request, *args, **kwargs)
           ^^^^^^^^^^^^^^^^^^^^^^^^^^^^^^^^^^^^^^
  File "C:\Users\Aliff Fahmi\Documents\GitHub\Local-LLM-and-OpenAI-PDF-QA\venv\Lib\site-packages\requests\adapters.py", line 519, in send
    raise ConnectionError(e, request=request)
requests.exceptions.ConnectionError: (MaxRetryError('HTTPSConnectionPool(host=\'huggingface.co\', port=443): Max retries exceeded with url: /api/models/google/flan-t5-xxl (Caused by NameResolutionError("<urllib3.connection.HTTPSConnection object at 0x000001C2240CD790>: Failed to resolve \'huggingface.co\' ([Errno 11001] getaddrinfo failed)"))'), '(Request ID: c446bcd4-0f4e-4aef-8370-d6b4c562d7d8)')